Workbook

Sheet Dashboard
A1: Customer Success Dashboard
A2: Synthetic SaaS data · 2,600 accounts · reporting month Sep 2026 · every number is a live formula
A4: ARR | E4: MRR growth (12 mo) | I4: Net revenue retention | M4: Gross revenue retention | Q4: NPS (12 mo) | U4: High Risk ARR
A5: =KPI_Summary!B6 -> 75595284 | E5: =KPI_Summary!B9 -> 0.3880458 | I5: =KPI_Summary!B12 -> 0.92290731 | M5: =KPI_Summary!B13 -> 0.87841833 | Q5: =KPI_Summary!B18 -> 27 | U5: =KPI_Summary!B22 -> 5736864

Sheet README
A1: SaaS Customer Success Analytics — Excel Workbook
A2: Synthetic practice dataset: 2,600 B2B SaaS accounts, Jan 2024 – Sep 2026 (reporting month: Sep 2026).
A4: HOW THIS WORKBOOK FITS THE PROJECT
A5: 1. SQL (customer_success_analysis.sql) cleans and aggregates the raw CSVs.
A6: 2. This workbook re-calculates the key metrics with formulas so you can see and change the logic.
A7: 3. Power BI uses the same data + DAX measures for the 5-page dashboard.
A9: TABS
A10: Assumptions — health-score weights and thresholds. Change a blue cell and every score updates.
A11: KPI_Summary — the executive numbers: ARR, MRR, churn, NRR/GRR, NPS, health mix, by segment.
A12: Monthly_MRR — 33 months of MRR, MRR movements (new / expansion / contraction / churn), logo churn.
A13: Health_Score — one row per active customer: raw inputs (from SQL) + formula-driven component scores.
A14: Retention_Cohort — customers paying in Sep 2025 and their MRR in Sep 2026, used for NRR / GRR.
... A25: c) Add a slicer to a PivotTable on Health_Score for csm_owner.

Sheet KPI_Summary
A1: Executive KPI Summary — reporting month Sep 2026
A2: Every number below is a live formula on the other tabs.
A4: REVENUE | D4: Health tier | E4: Customers | F4: ARR | G4: % of ARR
A5: Current MRR | B5: =INDEX(Monthly_MRR!B2:B34,COUNT(Monthly_MRR!B2:B34)) -> 6299607 | D5: Healthy | E5: =COUNTIF(Health_Score!$V$2:$V$2122,D5) -> 1102 | F5: =SUMIFS(Health_Score!$O$2:$O$2122,Health_Score!$V$2:$V$2122,D5) -> 33945924 | G5: =F5/SUM($F$5:$F$7) -> 0.44904817
A6: Current ARR | B6: =B5*12 -> 75595284 | D6: Needs Attention | E6: =COUNTIF(Health_Score!$V$2:$V$2122,D6) -> 901 | F6: =SUMIFS(Health_Score!$O$2:$O$2122,Health_Score!$V$2:$V$2122,D6) -> 35912496 | G6: =F6/SUM($F$5:$F$7) -> 0.47506265
A7: Paying customers | B7: =INDEX(Monthly_MRR!C2:C34,COUNT(Monthly_MRR!C2:C34)) -> 2121 | D7: High Risk | E7: =COUNTIF(Health_Score!$V$2:$V$2122,D7) -> 118 | F7: =SUMIFS(Health_Score!$O$2:$O$2122,Health_Score!$V$2:$V$2122,D7) -> 5736864 | G7: =F7/SUM($F$5:$F$7) -> 0.075889178
A8: Average ARR per customer | B8: =B6/B7 -> 35641.341 | D8: Total | E8: =SUM(E5:E7) -> 2121 | F8: =SUM(F5:F7) -> 75595284
A9: MRR growth, last 12 months | B9: =INDEX(Monthly_MRR!B2:B34,COUNT(Monthly_MRR!B2:B34))/INDEX(Monthly_MRR!B2:B34,COUNT(Monthly_MRR!B2:B34)-12)-1 -> 0.3880458
A10: Expansion MRR, last 12 months | B10: =SUM(OFFSET(Monthly_MRR!E2,COUNT(Monthly_MRR!B2:B34)-12,0,12,1)) -> 272516
A11: RETENTION (Sep 2025 → Sep 2026 cohort) | D11: Segment | E11: Active customers | F11: ARR | G11: Avg health | H11: High Risk | I11: NPS
A12: Net Revenue Retention (NRR) | B12: =SUM(Retention_Cohort!D2:D1621)/SUM(Retention_Cohort!C2:C1621) -> 0.92290731 | D12: SMB | E12: =COUNTIF(Health_Score!$C$2:$C$2122,D12) -> 1305 | F12: =SUMIFS(Health_Score!$O$2:$O$2122,Health_Score!$C$2:$C$2122,D12) -> 6061704 | G12: =AVERAGEIF(Health_Score!$C$2:$C$2122,D12,Health_Score!$U$2:$U$2122) -> 80.219923 | H12: =COUNTIFS(Health_Score!$C$2:$C$2122,D12,Health_Score!$V$2:$V$2122,"High Risk") -> 56 | I12: =ROUND(100*(COUNTIFS(NPS_Responses!$C$2:$C$4016,D12,NPS_Responses!$F$2:$F$4016,"Promoter")-COUNTIFS(NPS_Responses!$C$2:$C$4016,D12,NPS_Responses!$F$2:$F$4016,"Detractor"))/COUNTIF(NPS_Responses!$C$2:$C$4016,D12),0) -> 29
A13: Gross Revenue Retention (GRR) | B13: =SUM(Retention_Cohort!E2:E1621)/SUM(Retention_Cohort!C2:C1621) -> 0.87841833 | D13: Mid-Market | E13: =COUNTIF(Health_Score!$C$2:$C$2122,D13) -> 591 | F13: =SUMIFS(Health_Score!$O$2:$O$2122,Health_Score!$C$2:$C$2122,D13) -> 26217540 | G13: =AVERAGEIF(Health_Score!$C$2:$C$2122,D13,Health_Score!$U$2:$U$2122) -> 78.634518 | H13: =COUNTIFS(Health_Score!$C$2:$C$2122,D13,Health_Score!$V$2:$V$2122,"High Risk") -> 44 | I13: =ROUND(100*(COUNTIFS(NPS_Responses!$C$2:$C$4016,D13,NPS_Responses!$F$2:$F$4016,"Promoter")-COUNTIFS(NPS_Responses!$C$2:$C$4016,D13,NPS_Responses!$F$2:$F$4016,"Detractor"))/COUNTIF(NPS_Responses!$C$2:$C$4016,D13),0) -> 23
A14: Logo retention | B14: =SUM(Retention_Cohort!F2:F1621)/COUNT(Retention_Cohort!C2:C1621) -> 0.87839506 | D14: Enterprise | E14: =COUNTIF(Health_Score!$C$2:$C$2122,D14) -> 225 | F14: =SUMIFS(Health_Score!$O$2:$O$2122,Health_Score!$C$2:$C$2122,D14) -> 43316040 | G14: =AVERAGEIF(Health_Score!$C$2:$C$2122,D14,Health_Score!$U$2:$U$2122) -> 77.106667 | H14: =COUNTIFS(Health_Score!$C$2:$C$2122,D14,Health_Score!$V$2:$V$2122,"High Risk") -> 18 | I14: =ROUND(100*(COUNTIFS(NPS_Responses!$C$2:$C$4016,D14,NPS_Responses!$F$2:$F$4016,"Promoter")-COUNTIFS(NPS_Responses!$C$2:$C$4016,D14,NPS_Responses!$F$2:$F$4016,"Detractor"))/COUNTIF(NPS_Responses!$C$2:$C$4016,D14),0) -> 28
A15: Annual logo churn rate | B15: =1-B14 -> 0.12160494
A16: Avg monthly logo churn, last 12 months | B16: =AVERAGE(OFFSET(Monthly_MRR!M2,COUNT(Monthly_MRR!B2:B34)-12,0,12,1)) -> 0.010846907
A17: CUSTOMER SENTIMENT
A18: NPS (last 12 months) | B18: =ROUND(100*(COUNTIF(NPS_Responses!F2:F4016,"Promoter")-COUNTIF(NPS_Responses!F2:F4016,"Detractor"))/COUNTA(NPS_Responses!F2:F4016),0) -> 27
A19: Survey responses | B19: =COUNTA(NPS_Responses!F2:F4016) -> 4015
A20: CUSTOMER HEALTH (active customers)
A21: Average health score | B21: =AVERAGE(Health_Score!U2:U2122) -> 79.447902
A22: ARR in High Risk tier | B22: =SUMIFS(Health_Score!O2:O2122,Health_Score!V2:V2122,"High Risk") -> 5736864
A23: ARR in Needs Attention tier | B23: =SUMIFS(Health_Score!O2:O2122,Health_Score!V2:V2122,"Needs Attention") -> 35912496

Sheet Assumptions
A1: Assumption | B1: Value | C1: Notes
A2: Weight — Product usage | B2: 0.35 | C2: Share of health score
A3: Weight — NPS | B3: 0.2
A4: Weight — Support load | B4: 0.15
A5: Weight — Onboarding | B5: 0.1
A6: Weight — Revenue trend | B6: 0.2
A7: Weights total (must = 100%) | B7: =SUM(B2:B6) -> 1 | C7: Formula check
A8: Seat utilisation for full usage score | B8: 0.9 | C8: 90%+ active seats = 100 points
A9: Score if no NPS survey yet | B9: 50 | C9: Neutral default
A10: Healthy threshold (score ≥) | B10: 80
A11: Needs Attention threshold (score ≥) | B11: 65 | C11: Below this = High Risk
A12: Support score: 0–1 tickets in 90 days | B12: 100
A13: Support score: 2–3 tickets | B13: 75
A14: Support score: 4–6 tickets | B14: 50
A15: Support score: 7+ tickets | B15: 20
A16: Onboarding score: Completed On Time | B16: 100
A17: Onboarding score: Completed Late | B17: 60
A18: Onboarding score: In Progress | B18: 50
A19: Revenue trend: MRR up vs 3 months ago | B19: 100
A20: Revenue trend: flat (or new customer) | B20: 70
A21: Revenue trend: MRR down | B21: 30
A23: All values are design choices for this practice project (not from a published benchmark).

Sheet Health_Score
A1: account_id | B1: company_name | C1: segment | D1: plan | E1: region | F1: csm_owner | G1: renewal_date | H1: mrr_now | I1: mrr_3m_ago | J1: utilisation | K1: avg_features | L1: latest_nps | M1: tickets_90d | N1: onboarding_status | O1: ARR | P1: Usage score | Q1: NPS score | R1: Support score | S1: Onboarding score | T1: Growth score | U1: Health score | V1: Risk tier
A2: ACC-11401 | B2: Greenforge Group | C2: Enterprise | D2: Enterprise | E2: APAC | F2: Aisha Khan | G2: 2027-05-01 | H2: 36495 | I2: 31005 | J2: 0.748 | K2: 9.3 | L2: 10 | M2: 3 | N2: Completed On Time | O2: =H2*12 -> 437940 | P2: =MIN(100,ROUND(100*J2/Assumptions!$B$8,0)) -> 83 | Q2: =IF(L2="",Assumptions!$B$9,L2*10) -> 100 | R2: =IF(M2<=1,Assumptions!$B$12,IF(M2<=3,Assumptions!$B$13,IF(M2<=6,Assumptions!$B$14,Assumptions!$B$15))) -> 75 | S2: =IF(N2="Completed On Time",Assumptions!$B$16,IF(N2="Completed Late",Assumptions!$B$17,Assumptions!$B$18)) -> 100 | T2: =IF(I2=0,Assumptions!$B$20,IF(H2>I2,Assumptions!$B$19,IF(H2=I2,Assumptions!$B$20,Assumptions!$B$21))) -> 100 | U2: =ROUND(P2*Assumptions!$B$2+Q2*Assumptions!$B$3+R2*Assumptions!$B$4+S2*Assumptions!$B$5+T2*Assumptions!$B$6,0) -> 90 | V2: =IF(U2>=Assumptions!$B$10,"Healthy",IF(U2>=Assumptions!$B$11,"Needs Attention","High Risk")) -> Healthy
A3: ACC-12541 | B3: Blueflow Group | C3: Enterprise | D3: Enterprise | E3: North America | F3: Rahul Mehta | G3: 2027-12-01 | H3: 34785 | I3: 29655 | J3: 0.745 | K3: 9 | L3: 7 | M3: 2 | N3: Completed On Time | O3: =H3*12 -> 417420 | P3: =MIN(100,ROUND(100*J3/Assumptions!$B$8,0)) -> 83 | Q3: =IF(L3="",Assumptions!$B$9,L3*10) -> 70 | R3: =IF(M3<=1,Assumptions!$B$12,IF(M3<=3,Assumptions!$B$13,IF(M3<=6,Assumptions!$B$14,Assumptions!$B$15))) -> 75 | S3: =IF(N3="Completed On Time",Assumptions!$B$16,IF(N3="Completed Late",Assumptions!$B$17,Assumptions!$B$18)) -> 100 | T3: =IF(I3=0,Assumptions!$B$20,IF(H3>I3,Assumptions!$B$19,IF(H3=I3,Assumptions!$B$20,Assumptions!$B$21))) -> 100 | U3: =ROUND(P3*Assumptions!$B$2+Q3*Assumptions!$B$3+R3*Assumptions!$B$4+S3*Assumptions!$B$5+T3*Assumptions!$B$6,0) -> 84 | V3: =IF(U3>=Assumptions!$B$10,"Healthy",IF(U3>=Assumptions!$B$11,"Needs Attention","High Risk")) -> Healthy
A4: ACC-10519 | B4: Novapoint LLC | C4: Enterprise | D4: Enterprise | E4: LATAM | F4: Aisha Khan | G4: 2027-03-01 | H4: 34515 | I4: 34515 | J4: 0.79 | K4: 10.7 | L4: 8 | M4: 6 | N4: Completed On Time | O4: =H4*12 -> 414180 | P4: =MIN(100,ROUND(100*J4/Assumptions!$B$8,0)) -> 88 | Q4: =IF(L4="",Assumptions!$B$9,L4*10) -> 80 | R4: =IF(M4<=1,Assumptions!$B$12,IF(M4<=3,Assumptions!$B$13,IF(M4<=6,Assumptions!$B$14,Assumptions!$B$15))) -> 50 | S4: =IF(N4="Completed On Time",Assumptions!$B$16,IF(N4="Completed Late",Assumptions!$B$17,Assumptions!$B$18)) -> 100 | T4: =IF(I4=0,Assumptions!$B$20,IF(H4>I4,Assumptions!$B$19,IF(H4=I4,Assumptions!$B$20,Assumptions!$B$21))) -> 70 | U4: =ROUND(P4*Assumptions!$B$2+Q4*Assumptions!$B$3+R4*Assumptions!$B$4+S4*Assumptions!$B$5+T4*Assumptions!$B$6,0) -> 78 | V4: =IF(U4>=Assumptions!$B$10,"Healthy",IF(U4>=Assumptions!$B$11,"Needs Attention","High Risk")) -> Needs Attention
A5: ACC-11133 | B5: Atlasly Inc | C5: Enterprise | D5: Enterprise | E5: EMEA | F5: Priya Sharma | G5: 2027-12-01 | H5: 32985 | I5: 32985 | J5: 0.835 | K5: 10 | L5: 8 | M5: 4 | N5: Completed On Time | O5: =H5*12 -> 395820 | P5: =MIN(100,ROUND(100*J5/Assumptions!$B$8,0)) -> 93 | Q5: =IF(L5="",Assumptions!$B$9,L5*10) -> 80 | R5: =IF(M5<=1,Assumptions!$B$12,IF(M5<=3,Assumptions!$B$13,IF(M5<=6,Assumptions!$B$14,Assumptions!$B$15))) -> 50 | S5: =IF(N5="Completed On Time",Assumptions!$B$16,IF(N5="Completed Late",Assumptions!$B$17,Assumptions!$B$18)) -> 100 | T5: =IF(I5=0,Assumptions!$B$20,IF(H5>I5,Assumptions!$B$19,IF(H5=I5,Assumptions!$B$20,Assumptions!$B$21))) -> 70 | U5: =ROUND(P5*Assumptions!$B$2+Q5*Assumptions!$B$3+R5*Assumptions!$B$4+S5*Assumptions!$B$5+T5*Assumptions!$B$6,0) -> 80 | V5: =IF(U5>=Assumptions!$B$10,"Healthy",IF(U5>=Assumptions!$B$11,"Needs Attention","High Risk")) -> Healthy
A6: ACC-12426 | B6: Primeflow Co | C6: Enterprise | D6: Enterprise | E6: APAC | F6: Sofia Alvarez | G6: 2027-02-01 | H6: 32760 | I6: 32760 | J6: 0.555 | K6: 7 | L6: 7 | M6: 10 | N6: Completed On Time | O6: =H6*12 -> 393120 | P6: =MIN(100,ROUND(100*J6/Assumptions!$B$8,0)) -> 62 | Q6: =IF(L6="",Assumptions!$B$9,L6*10) -> 70 | R6: =IF(M6<=1,Assumptions!$B$12,IF(M6<=3,Assumptions!$B$13,IF(M6<=6,Assumptions!$B$14,Assumptions!$B$15))) -> 20 | S6: =IF(N6="Completed On Time",Assumptions!$B$16,IF(N6="Completed Late",Assumptions!$B$17,Assumptions!$B$18)) -> 100 | T6: =IF(I6=0,Assumptions!$B$20,IF(H6>I6,Assumptions!$B$19,IF(H6=I6,Assumptions!$B$20,Assumptions!$B$21))) -> 70 | U6: =ROUND(P6*Assumptions!$B$2+Q6*Assumptions!$B$3+R6*Assumptions!$B$4+S6*Assumptions!$B$5+T6*Assumptions!$B$6,0) -> 63 | V6: =IF(U6>=Assumptions!$B$10,"Healthy",IF(U6>=Assumptions!$B$11,"Needs Attention","High Risk")) -> High Risk
A7: ACC-11722 | B7: Apexwave Systems | C7: Enterprise | D7: Enterprise | E7: North America | F7: Rahul Mehta | G7: 2027-11-01 | H7: 31275 | I7: 31275 | J7: 0.894 | K7: 11 | L7: 10 | M7: 1 | N7: Completed On Time | O7: =H7*12 -> 375300 | P7: =MIN(100,ROUND(100*J7/Assumptions!$B$8,0)) -> 99 | Q7: =IF(L7="",Assumptions!$B$9,L7*10) -> 100 | R7: =IF(M7<=1,Assumptions!$B$12,IF(M7<=3,Assumptions!$B$13,IF(M7<=6,Assumptions!$B$14,Assumptions!$B$15))) -> 100 | S7: =IF(N7="Completed On Time",Assumptions!$B$16,IF(N7="Completed Late",Assumptions!$B$17,Assumptions!$B$18)) -> 100 | T7: =IF(I7=0,Assumptions!$B$20,IF(H7>I7,Assumptions!$B$19,IF(H7=I7,Assumptions!$B$20,Assumptions!$B$21))) -> 70 | U7: =ROUND(P7*Assumptions!$B$2+Q7*Assumptions!$B$3+R7*Assumptions!$B$4+S7*Assumptions!$B$5+T7*Assumptions!$B$6,0) -> 94 | V7: =IF(U7>=Assumptions!$B$10,"Healthy",IF(U7>=Assumptions!$B$11,"Needs Attention","High Risk")) -> Healthy
A8: ACC-12504 | B8: Orbitworks LLC | C8: Enterprise | D8: Enterprise | E8: APAC | F8: Lucas Martin | G8: 2027-04-01 | H8: 30195 | I8: 30195 | J8: 0.747 | K8: 9.3 | L8: 9 | M8: 2 | N8: Completed On Time | O8: =H8*12 -> 362340 | P8: =MIN(100,ROUND(100*J8/Assumptions!$B$8,0)) -> 83 | Q8: =IF(L8="",Assumptions!$B$9,L8*10) -> 90 | R8: =IF(M8<=1,Assumptions!$B$12,IF(M8<=3,Assumptions!$B$13,IF(M8<=6,Assumptions!$B$14,Assumptions!$B$15))) -> 75 | S8: =IF(N8="Completed On Time",Assumptions!$B$16,IF(N8="Completed Late",Assumptions!$B$17,Assumptions!$B$18)) -> 100 | T8: =IF(I8=0,Assumptions!$B$20,IF(H8>I8,Assumptions!$B$19,IF(H8=I8,Assumptions!$B$20,Assumptions!$B$21))) -> 70 | U8: =ROUND(P8*Assumptions!$B$2+Q8*Assumptions!$B$3+R8*Assumptions!$B$4+S8*Assumptions!$B$5+T8*Assumptions!$B$6,0) -> 82 | V8: =IF(U8>=Assumptions!$B$10,"Healthy",IF(U8>=Assumptions!$B$11,"Needs Attention","High Risk")) -> Healthy
A9: ACC-10374 | B9: Clearbridge Ltd | C9: Enterprise | D9: Enterprise | E9: APAC | F9: Aisha Khan | G9: 2027-06-01 | H9: 29925 | I9: 29925 | J9: 0.646 | K9: 7.7 | L9: 8 | M9: 9 | N9: Completed Late | O9: =H9*12 -> 359100 | P9: =MIN(100,ROUND(100*J9/Assumptions!$B$8,0)) -> 72 | Q9: =IF(L9="",Assumptions!$B$9,L9*10) -> 80 | R9: =IF(M9<=1,Assumptions!$B$12,IF(M9<=3,Assumptions!$B$13,IF(M9<=6,Assumptions!$B$14,Assumptions!$B$15))) -> 20 | S9: =IF(N9="Completed On Time",Assumptions!$B$16,IF(N9="Completed Late",Assumptions!$B$17,Assumptions!$B$18)) -> 60 | T9: =IF(I9=0,Assumptions!$B$20,IF(H9>I9,Assumptions!$B$19,IF(H9=I9,Assumptions!$B$20,Assumptions!$B$21))) -> 70 | U9: =ROUND(P9*Assumptions!$B$2+Q9*Assumptions!$B$3+R9*Assumptions!$B$4+S9*Assumptions!$B$5+T9*Assumptions!$B$6,0) -> 64 | V9: =IF(U9>=Assumptions!$B$10,"Healthy",IF(U9>=Assumptions!$B$11,"Needs Attention","High Risk")) -> High Risk
A10: ACC-11225 | B10: Trueline Ltd | C10: Enterprise | D10: Enterprise | E10: North America | F10: James Carter | G10: 2027-05-01 | H10: 29925 | I10: 29925 | J10: 0.823 | K10: 10 | L10: 10 | M10: 4 | N10: Completed On Time | O10: =H10*12 -> 359100 | P10: =MIN(100,ROUND(100*J10/Assumptions!$B$8,0)) -> 91 | Q10: =IF(L10="",Assumptions!$B$9,L10*10) -> 100 | R10: =IF(M10<=1,Assumptions!$B$12,IF(M10<=3,Assumptions!$B$13,IF(M10<=6,Assumptions!$B$14,Assumptions!$B$15))) -> 50 | S10: =IF(N10="Completed On Time",Assumptions!$B$16,IF(N10="Completed Late",Assumptions!$B$17,Assumptions!$B$18)) -> 100 | T10: =IF(I10=0,Assumptions!$B$20,IF(H10>I10,Assumptions!$B$19,IF(H10=I10,Assumptions!$B$20,Assumptions!$B$21))) -> 70 | U10: =ROUND(P10*Assumptions!$B$2+Q10*Assumptions!$B$3+R10*Assumptions!$B$4+S10*Assumptions!$B$5+T10*Assumptions!$B$6,0) -> 83 | V10: =IF(U10>=Assumptions!$B$10,"Healthy",IF(U10>=Assumptions!$B$11,"Needs Attention","High Risk")) -> Healthy
A11: ACC-12391 | B11: Lumenlogic Ltd | C11: Enterprise | D11: Enterprise | E11: EMEA | F11: Neha Iyer | G11: 2027-11-01 | H11: 29745 | I11: 29745 | J11: 0.751 | K11: 8 | L11: 8 | M11: 6 | N11: Completed On Time | O11: =H11*12 -> 356940 | P11: =MIN(100,ROUND(100*J11/Assumptions!$B$8,0)) -> 83 | Q11: =IF(L11="",Assumptions!$B$9,L11*10) -> 80 | R11: =IF(M11<=1,Assumptions!$B$12,IF(M11<=3,Assumptions!$B$13,IF(M11<=6,Assumptions!$B$14,Assumptions!$B$15))) -> 50 | S11: =IF(N11="Completed On Time",Assumptions!$B$16,IF(N11="Completed Late",Assumptions!$B$17,Assumptions!$B$18)) -> 100 | T11: =IF(I11=0,Assumptions!$B$20,IF(H11>I11,Assumptions!$B$19,IF(H11=I11,Assumptions!$B$20,Assumptions!$B$21))) -> 70 | U11: =ROUND(P11*Assumptions!$B$2+Q11*Assumptions!$B$3+R11*Assumptions!$B$4+S11*Assumptions!$B$5+T11*Assumptions!$B$6,0) -> 77 | V11: =IF(U11>=Assumptions!$B$10,"Healthy",IF(U11>=Assumptions!$B$11,"Needs Attention","High Risk")) -> Needs Attention
A12: ACC-10382 | B12: Coreforge Co | C12: Enterprise | D12: Enterprise | E12: LATAM | F12: Priya Sharma | G12: 2027-06-01 | H12: 28125 | I12: 23175 | J12: 0.679 | K12: 7.3 | L12: 7 | M12: 8 | N12: Completed Late | O12: =H12*12 -> 337500 | P12: =MIN(100,ROUND(100*J12/Assumptions!$B$8,0)) -> 75 | Q12: =IF(L12="",Assumptions!$B$9,L12*10) -> 70 | R12: =IF(M12<=1,Assumptions!$B$12,IF(M12<=3,Assumptions!$B$13,IF(M12<=6,Assumptions!$B$14,Assumptions!$B$15))) -> 20 | S12: =IF(N12="Completed On Time",Assumptions!$B$16,IF(N12="Completed Late",Assumptions!$B$17,Assumptions!$B$18)) -> 60 | T12: =IF(I12=0,Assumptions!$B$20,IF(H12>I12,Assumptions!$B$19,IF(H12=I12,Assumptions!$B$20,Assumptions!$B$21))) -> 100 | U12: =ROUND(P12*Assumptions!$B$2+Q12*Assumptions!$B$3+R12*Assumptions!$B$4+S12*Assumptions!$B$5+T12*Assumptions!$B$6,0) -> 69 | V12: =IF(U12>=Assumptions!$B$10,"Healthy",IF(U12>=Assumptions!$B$11,"Needs Attention","High Risk")) -> Needs Attention
A13: ACC-12420 | B13: Clearly Inc | C13: Enterprise | D13: Enterprise | E13: North America | F13: Sofia Alvarez | G13: 2027-09-01 | H13: 28035 | I13: 28035 | J13: 0.775 | K13: 10.3 | L13: 8 | M13: 2 | N13: Completed On Time | O13: =H13*12 -> 336420 | P13: =MIN(100,ROUND(100*J13/Assumptions!$B$8,0)) -> 86 | Q13: =IF(L13="",Assumptions!$B$9,L13*10) -> 80 | R13: =IF(M13<=1,Assumptions!$B$12,IF(M13<=3,Assumptions!$B$13,IF(M13<=6,Assumptions!$B$14,Assumptions!$B$15))) -> 75 | S13: =IF(N13="Completed On Time",Assumptions!$B$16,IF(N13="Completed Late",Assumptions!$B$17,Assumptions!$B$18)) -> 100 | T13: =IF(I13=0,Assumptions!$B$20,IF(H13>I13,Assumptions!$B$19,IF(H13=I13,Assumptions!$B$20,Assumptions!$B$21))) -> 70 | U13: =ROUND(P13*Assumptions!$B$2+Q13*Assumptions!$B$3+R13*Assumptions!$B$4+S13*Assumptions!$B$5+T13*Assumptions!$B$6,0) -> 81 | V13: =IF(U13>=Assumptions!$B$10,"Healthy",IF(U13>=Assumptions!$B$11,"Needs Attention","High Risk")) -> Healthy
... A29: ACC-11929 | B29: Northworks Group | C29: Enterprise | D29: Enterprise | E29: EMEA | F29: Neha Iyer | G29: 2027-11-01 | H29: 25695 | I29: 25695 | J29: 0.572 | K29: 7 | L29: 4 | M29: 6 | N29: Completed Late | O29: =H29*12 -> 308340 | P29: =MIN(100,ROUND(100*J29/Assumptions!$B$8,0)) -> 64 | Q29: =IF(L29="",Assumptions!$B$9,L29*10) -> 40 | R29: =IF(M29<=1,Assumptions!$B$12,IF(M29<=3,Assumptions!$B$13,IF(M29<=6,Assumptions!$B$14,Assumptions!$B$15))) -> 50 | S29: =IF(N29="Completed On Time",Assumptions!$B$16,IF(N29="Completed Late",Assumptions!$B$17,Assumptions!$B$18)) -> 60 | T29: =IF(I29=0,Assumptions!$B$20,IF(H29>I29,Assumptions!$B$19,IF(H29=I29,Assumptions!$B$20,Assumptions!$B$21))) -> 70 | U29: =ROUND(P29*Assumptions!$B$2+Q29*Assumptions!$B$3+R29*Assumptions!$B$4+S29*Assumptions!$B$5+T29*Assumptions!$B$6,0) -> 58 | V29: =IF(U29>=Assumptions!$B$10,"Healthy",IF(U29>=Assumptions!$B$11,"Needs Attention","High Risk")) -> High Risk
A30: ACC-10666 | B30: Corely Group | C30: Enterprise | D30: Enterprise | E30: North America | F30: Emily Chen | G30: 2027-08-01 | H30: 25515 | I30: 0 | J30: 0.715 | K30: 10 | M30: 4 | N30: In Progress | O30: =H30*12 -> 306180 | P30: =MIN(100,ROUND(100*J30/Assumptions!$B$8,0)) -> 79 | Q30: =IF(L30="",Assumptions!$B$9,L30*10) -> 50 | R30: =IF(M30<=1,Assumptions!$B$12,IF(M30<=3,Assumptions!$B$13,IF(M30<=6,Assumptions!$B$14,Assumptions!$B$15))) -> 50 | S30: =IF(N30="Completed On Time",Assumptions!$B$16,IF(N30="Completed Late",Assumptions!$B$17,Assumptions!$B$18)) -> 50 | T30: =IF(I30=0,Assumptions!$B$20,IF(H30>I30,Assumptions!$B$19,IF(H30=I30,Assumptions!$B$20,Assumptions!$B$21))) -> 70 | U30: =ROUND(P30*Assumptions!$B$2+Q30*Assumptions!$B$3+R30*Assumptions!$B$4+S30*Assumptions!$B$5+T30*Assumptions!$B$6,0) -> 64 | V30: =IF(U30>=Assumptions!$B$10,"Healthy",IF(U30>=Assumptions!$B$11,"Needs Attention","High Risk")) -> High Risk
A31: ACC-10295 | B31: Urbanwave Group | C31: Enterprise | D31: Enterprise | E31: EMEA | F31: Daniel Brooks | G31: 2027-01-01 | H31: 25200 | I31: 25200 | J31: 0.594 | K31: 8 | L31: 6 | M31: 3 | N31: Completed On Time | O31: =H31*12 -> 302400 | P31: =MIN(100,ROUND(100*J31/Assumptions!$B$8,0)) -> 66 | Q31: =IF(L31="",Assumptions!$B$9,L31*10) -> 60 | R31: =IF(M31<=1,Assumptions!$B$12,IF(M31<=3,Assumptions!$B$13,IF(M31<=6,Assumptions!$B$14,Assumptions!$B$15))) -> 75 | S31: =IF(N31="Completed On Time",Assumptions!$B$16,IF(N31="Completed Late",Assumptions!$B$17,Assumptions!$B$18)) -> 100 | T31: =IF(I31=0,Assumptions!$B$20,IF(H31>I31,Assumptions!$B$19,IF(H31=I31,Assumptions!$B$20,Assumptions!$B$21))) -> 70 | U31: =ROUND(P31*Assumptions!$B$2+Q31*Assumptions!$B$3+R31*Assumptions!$B$4+S31*Assumptions!$B$5+T31*Assumptions!$B$6,0) -> 70 | V31: =IF(U31>=Assumptions!$B$10,"Healthy",IF(U31>=Assumptions!$B$11,"Needs Attention","High Risk")) -> Needs Attention
A32: ACC-10351 | B32: Apexsphere Inc | C32: Enterprise | D32: Enterprise | E32: APAC | F32: Lucas Martin | G32: 2027-10-01 | H32: 24975 | I32: 24975 | J32: 0.733 | K32: 10 | L32: 8 | M32: 5 | N32: Completed On Time | O32: =H32*12 -> 299700 | P32: =MIN(100,ROUND(100*J32/Assumptions!$B$8,0)) -> 81 | Q32: =IF(L32="",Assumptions!$B$9,L32*10) -> 80 | R32: =IF(M32<=1,Assumptions!$B$12,IF(M32<=3,Assumptions!$B$13,IF(M32<=6,Assumptions!$B$14,Assumptions!$B$15))) -> 50 | S32: =IF(N32="Completed On Time",Assumptions!$B$16,IF(N32="Completed Late",Assumptions!$B$17,Assumptions!$B$18)) -> 100 | T32: =IF(I32=0,Assumptions!$B$20,IF(H32>I32,Assumptions!$B$19,IF(H32=I32,Assumptions!$B$20,Assumptions!$B$21))) -> 70 | U32: =ROUND(P32*Assumptions!$B$2+Q32*Assumptions!$B$3+R32*Assumptions!$B$4+S32*Assumptions!$B$5+T32*Assumptions!$B$6,0) -> 76 | V32: =IF(U32>=Assumptions!$B$10,"Healthy",IF(U32>=Assumptions!$B$11,"Needs Attention","High Risk")) -> Needs Attention
A33: ACC-12177 | B33: Urbanlabs Solutions | C33: Enterprise | D33: Enterprise | E33: APAC | F33: Lucas Martin | G33: 2027-06-01 | H33: 24930 | I33: 24930 | J33: 0.695 | K33: 8.3 | L33: 7 | M33: 8 | N33: Completed On Time | O33: =H33*12 -> 299160 | P33: =MIN(100,ROUND(100*J33/Assumptions!$B$8,0)) -> 77 | Q33: =IF(L33="",Assumptions!$B$9,L33*10) -> 70 | R33: =IF(M33<=1,Assumptions!$B$12,IF(M33<=3,Assumptions!$B$13,IF(M33<=6,Assumptions!$B$14,Assumptions!$B$15))) -> 20 | S33: =IF(N33="Completed On Time",Assumptions!$B$16,IF(N33="Completed Late",Assumptions!$B$17,Assumptions!$B$18)) -> 100 | T33: =IF(I33=0,Assumptions!$B$20,IF(H33>I33,Assumptions!$B$19,IF(H33=I33,Assumptions!$B$20,Assumptions!$B$21))) -> 70 | U33: =ROUND(P33*Assumptions!$B$2+Q33*Assumptions!$B$3+R33*Assumptions!$B$4+S33*Assumptions!$B$5+T33*Assumptions!$B$6,0) -> 68 | V33: =IF(U33>=Assumptions!$B$10,"Healthy",IF(U33>=Assumptions!$B$11,"Needs Attention","High Risk")) -> Needs Attention
A34: ACC-11005 | B34: Novaworks Ltd | C34: Enterprise | D34: Enterprise | E34: North America | F34: Aisha Khan | G34: 2027-06-01 | H34: 24570 | I34: 24570 | J34: 0.766 | K34: 10 | L34: 9 | M34: 2 | N34: Completed On Time | O34: =H34*12 -> 294840 | P34: =MIN(100,ROUND(100*J34/Assumptions!$B$8,0)) -> 85 | Q34: =IF(L34="",Assumptions!$B$9,L34*10) -> 90 | R34: =IF(M34<=1,Assumptions!$B$12,IF(M34<=3,Assumptions!$B$13,IF(M34<=6,Assumptions!$B$14,Assumptions!$B$15))) -> 75 | S34: =IF(N34="Completed On Time",Assumptions!$B$16,IF(N34="Completed Late",Assumptions!$B$17,Assumptions!$B$18)) -> 100 | T34: =IF(I34=0,Assumptions!$B$20,IF(H34>I34,Assumptions!$B$19,IF(H34=I34,Assumptions!$B$20,Assumptions!$B$21))) -> 70 | U34: =ROUND(P34*Assumptions!$B$2+Q34*Assumptions!$B$3+R34*Assumptions!$B$4+S34*Assumptions!$B$5+T34*Assumptions!$B$6,0) -> 83 | V34: =IF(U34>=Assumptions!$B$10,"Healthy",IF(U34>=Assumptions!$B$11,"Needs Attention","High Risk")) -> Healthy
A35: ACC-10864 | B35: Vertexworks Group | C35: Enterprise | D35: Enterprise | E35: EMEA | F35: Priya Sharma | G35: 2027-01-01 | H35: 24525 | I35: 19980 | J35: 0.754 | K35: 8.7 | L35: 6 | M35: 7 | N35: Completed On Time | O35: =H35*12 -> 294300 | P35: =MIN(100,ROUND(100*J35/Assumptions!$B$8,0)) -> 84 | Q35: =IF(L35="",Assumptions!$B$9,L35*10) -> 60 | R35: =IF(M35<=1,Assumptions!$B$12,IF(M35<=3,Assumptions!$B$13,IF(M35<=6,Assumptions!$B$14,Assumptions!$B$15))) -> 20 | S35: =IF(N35="Completed On Time",Assumptions!$B$16,IF(N35="Completed Late",Assumptions!$B$17,Assumptions!$B$18)) -> 100 | T35: =IF(I35=0,Assumptions!$B$20,IF(H35>I35,Assumptions!$B$19,IF(H35=I35,Assumptions!$B$20,Assumptions!$B$21))) -> 100 | U35: =ROUND(P35*Assumptions!$B$2+Q35*Assumptions!$B$3+R35*Assumptions!$B$4+S35*Assumptions!$B$5+T35*Assumptions!$B$6,0) -> 74 | V35: =IF(U35>=Assumptions!$B$10,"Healthy",IF(U35>=Assumptions!$B$11,"Needs Attention","High Risk")) -> Needs Attention
A36: ACC-11289 | B36: Urbanmind Systems | C36: Enterprise | D36: Enterprise | E36: North America | F36: Neha Iyer | G36: 2027-06-01 | H36: 24525 | I36: 24525 | J36: 0.859 | K36: 10.3 | L36: 10 | M36: 2 | N36: Completed On Time | O36: =H36*12 -> 294300 | P36: =MIN(100,ROUND(100*J36/Assumptions!$B$8,0)) -> 95 | Q36: =IF(L36="",Assumptions!$B$9,L36*10) -> 100 | R36: =IF(M36<=1,Assumptions!$B$12,IF(M36<=3,Assumptions!$B$13,IF(M36<=6,Assumptions!$B$14,Assumptions!$B$15))) -> 75 | S36: =IF(N36="Completed On Time",Assumptions!$B$16,IF(N36="Completed Late",Assumptions!$B$17,Assumptions!$B$18)) -> 100 | T36: =IF(I36=0,Assumptions!$B$20,IF(H36>I36,Assumptions!$B$19,IF(H36=I36,Assumptions!$B$20,Assumptions!$B$21))) -> 70 | U36: =ROUND(P36*Assumptions!$B$2+Q36*Assumptions!$B$3+R36*Assumptions!$B$4+S36*Assumptions!$B$5+T36*Assumptions!$B$6,0) -> 89 | V36: =IF(U36>=Assumptions!$B$10,"Healthy",IF(U36>=Assumptions!$B$11,"Needs Attention","High Risk")) -> Healthy
A37: ACC-11958 | B37: Vertexmind Solutions | C37: Enterprise | D37: Enterprise | E37: EMEA | F37: James Carter | G37: 2027-12-01 | H37: 24345 | I37: 18990 | J37: 0.941 | K37: 11.3 | L37: 10 | M37: 3 | N37: Completed On Time | O37: =H37*12 -> 292140 | P37: =MIN(100,ROUND(100*J37/Assumptions!$B$8,0)) -> 100 | Q37: =IF(L37="",Assumptions!$B$9,L37*10) -> 100 | R37: =IF(M37<=1,Assumptions!$B$12,IF(M37<=3,Assumptions!$B$13,IF(M37<=6,Assumptions!$B$14,Assumptions!$B$15))) -> 75 | S37: =IF(N37="Completed On Time",Assumptions!$B$16,IF(N37="Completed Late",Assumptions!$B$17,Assumptions!$B$18)) -> 100 | T37: =IF(I37=0,Assumptions!$B$20,IF(H37>I37,Assumptions!$B$19,IF(H37=I37,Assumptions!$B$20,Assumptions!$B$21))) -> 100 | U37: =ROUND(P37*Assumptions!$B$2+Q37*Assumptions!$B$3+R37*Assumptions!$B$4+S37*Assumptions!$B$5+T37*Assumptions!$B$6,0) -> 96 | V37: =IF(U37>=Assumptions!$B$10,"Healthy",IF(U37>=Assumptions!$B$11,"Needs Attention","High Risk")) -> Healthy
A38: ACC-11206 | B38: Greencraft Inc | C38: Enterprise | D38: Enterprise | E38: APAC | F38: Emily Chen | G38: 2027-04-01 | H38: 24300 | I38: 24300 | J38: 0.612 | K38: 7.3 | L38: 6 | M38: 6 | N38: Completed On Time | O38: =H38*12 -> 291600 | P38: =MIN(100,ROUND(100*J38/Assumptions!$B$8,0)) -> 68 | Q38: =IF(L38="",Assumptions!$B$9,L38*10) -> 60 | R38: =IF(M38<=1,Assumptions!$B$12,IF(M38<=3,Assumptions!$B$13,IF(M38<=6,Assumptions!$B$14,Assumptions!$B$15))) -> 50 | S38: =IF(N38="Completed On Time",Assumptions!$B$16,IF(N38="Completed Late",Assumptions!$B$17,Assumptions!$B$18)) -> 100 | T38: =IF(I38=0,Assumptions!$B$20,IF(H38>I38,Assumptions!$B$19,IF(H38=I38,Assumptions!$B$20,Assumptions!$B$21))) -> 70 | U38: =ROUND(P38*Assumptions!$B$2+Q38*Assumptions!$B$3+R38*Assumptions!$B$4+S38*Assumptions!$B$5+T38*Assumptions!$B$6,0) -> 67 | V38: =IF(U38>=Assumptions!$B$10,"Healthy",IF(U38>=Assumptions!$B$11,"Needs Attention","High Risk")) -> Needs Attention
A39: ACC-10096 | B39: Primegrid Systems | C39: Enterprise | D39: Enterprise | E39: APAC | F39: Emily Chen | G39: 2027-07-01 | H39: 24165 | I39: 24165 | J39: 0.762 | K39: 9 | L39: 8 | M39: 0 | N39: Completed Late | O39: =H39*12 -> 289980 | P39: =MIN(100,ROUND(100*J39/Assumptions!$B$8,0)) -> 85 | Q39: =IF(L39="",Assumptions!$B$9,L39*10) -> 80 | R39: =IF(M39<=1,Assumptions!$B$12,IF(M39<=3,Assumptions!$B$13,IF(M39<=6,Assumptions!$B$14,Assumptions!$B$15))) -> 100 | S39: =IF(N39="Completed On Time",Assumptions!$B$16,IF(N39="Completed Late",Assumptions!$B$17,Assumptions!$B$18)) -> 60 | T39: =IF(I39=0,Assumptions!$B$20,IF(H39>I39,Assumptions!$B$19,IF(H39=I39,Assumptions!$B$20,Assumptions!$B$21))) -> 70 | U39: =ROUND(P39*Assumptions!$B$2+Q39*Assumptions!$B$3+R39*Assumptions!$B$4+S39*Assumptions!$B$5+T39*Assumptions!$B$6,0) -> 81 | V39: =IF(U39>=Assumptions!$B$10,"Healthy",IF(U39>=Assumptions!$B$11,"Needs Attention","High Risk")) -> Healthy
A40: ACC-11762 | B40: Boldforge Ltd | C40: Enterprise | D40: Enterprise | E40: EMEA | F40: James Carter | G40: 2027-07-01 | H40: 24030 | I40: 0 | J40: 0.752 | K40: 10 | M40: 5 | N40: In Progress | O40: =H40*12 -> 288360 | P40: =MIN(100,ROUND(100*J40/Assumptions!$B$8,0)) -> 84 | Q40: =IF(L40="",Assumptions!$B$9,L40*10) -> 50 | R40: =IF(M40<=1,Assumptions!$B$12,IF(M40<=3,Assumptions!$B$13,IF(M40<=6,Assumptions!$B$14,Assumptions!$B$15))) -> 50 | S40: =IF(N40="Completed On Time",Assumptions!$B$16,IF(N40="Completed Late",Assumptions!$B$17,Assumptions!$B$18)) -> 50 | T40: =IF(I40=0,Assumptions!$B$20,IF(H40>I40,Assumptions!$B$19,IF(H40=I40,Assumptions!$B$20,Assumptions!$B$21))) -> 70 | U40: =ROUND(P40*Assumptions!$B$2+Q40*Assumptions!$B$3+R40*Assumptions!$B$4+S40*Assumptions!$B$5+T40*Assumptions!$B$6,0) -> 66 | V40: =IF(U40>=Assumptions!$B$10,"Healthy",IF(U40>=Assumptions!$B$11,"Needs Attention","High Risk")) -> Needs Attention
A41: ACC-11816 | B41: Primescale Ltd | C41: Enterprise | D41: Enterprise | E41: APAC | F41: Marco Rossi | G41: 2027-07-01 | H41: 23670 | I41: 23670 | J41: 0.719 | K41: 9.7 | L41: 8 | M41: 2 | N41: Completed Late | O41: =H41*12 -> 284040 | P41: =MIN(100,ROUND(100*J41/Assumptions!$B$8,0)) -> 80 | Q41: =IF(L41="",Assumptions!$B$9,L41*10) -> 80 | R41: =IF(M41<=1,Assumptions!$B$12,IF(M41<=3,Assumptions!$B$13,IF(M41<=6,Assumptions!$B$14,Assumptions!$B$15))) -> 75 | S41: =IF(N41="Completed On Time",Assumptions!$B$16,IF(N41="Completed Late",Assumptions!$B$17,Assumptions!$B$18)) -> 60 | T41: =IF(I41=0,Assumptions!$B$20,IF(H41>I41,Assumptions!$B$19,IF(H41=I41,Assumptions!$B$20,Assumptions!$B$21))) -> 70 | U41: =ROUND(P41*Assumptions!$B$2+Q41*Assumptions!$B$3+R41*Assumptions!$B$4+S41*Assumptions!$B$5+T41*Assumptions!$B$6,0) -> 75 | V41: =IF(U41>=Assumptions!$B$10,"Healthy",IF(U41>=Assumptions!$B$11,"Needs Attention","High Risk")) -> Needs Attention
A42: ACC-11542 | B42: Brightgrid Solutions | C42: Enterprise | D42: Enterprise | E42: APAC | F42: Rahul Mehta | G42: 2027-05-01 | H42: 23355 | I42: 23355 | J42: 0.662 | K42: 7.3 | L42: 7 | M42: 3 | N42: Completed Late | O42: =H42*12 -> 280260 | P42: =MIN(100,ROUND(100*J42/Assumptions!$B$8,0)) -> 74 | Q42: =IF(L42="",Assumptions!$B$9,L42*10) -> 70 | R42: =IF(M42<=1,Assumptions!$B$12,IF(M42<=3,Assumptions!$B$13,IF(M42<=6,Assumptions!$B$14,Assumptions!$B$15))) -> 75 | S42: =IF(N42="Completed On Time",Assumptions!$B$16,IF(N42="Completed Late",Assumptions!$B$17,Assumptions!$B$18)) -> 60 | T42: =IF(I42=0,Assumptions!$B$20,IF(H42>I42,Assumptions!$B$19,IF(H42=I42,Assumptions!$B$20,Assumptions!$B$21))) -> 70 | U42: =ROUND(P42*Assumptions!$B$2+Q42*Assumptions!$B$3+R42*Assumptions!$B$4+S42*Assumptions!$B$5+T42*Assumptions!$B$6,0) -> 71 | V42: =IF(U42>=Assumptions!$B$10,"Healthy",IF(U42>=Assumptions!$B$11,"Needs Attention","High Risk")) -> Needs Attention
A43: ACC-12463 | B43: Primepoint Solutions | C43: Enterprise | D43: Enterprise | E43: EMEA | F43: Sofia Alvarez | G43: 2027-03-01 | H43: 23355 | I43: 23355 | J43: 0.732 | K43: 8 | L43: 10 | M43: 3 | N43: Completed On Time | O43: =H43*12 -> 280260 | P43: =MIN(100,ROUND(100*J43/Assumptions!$B$8,0)) -> 81 | Q43: =IF(L43="",Assumptions!$B$9,L43*10) -> 100 | R43: =IF(M43<=1,Assumptions!$B$12,IF(M43<=3,Assumptions!$B$13,IF(M43<=6,Assumptions!$B$14,Assumptions!$B$15))) -> 75 | S43: =IF(N43="Completed On Time",Assumptions!$B$16,IF(N43="Completed Late",Assumptions!$B$17,Assumptions!$B$18)) -> 100 | T43: =IF(I43=0,Assumptions!$B$20,IF(H43>I43,Assumptions!$B$19,IF(H43=I43,Assumptions!$B$20,Assumptions!$B$21))) -> 70 | U43: =ROUND(P43*Assumptions!$B$2+Q43*Assumptions!$B$3+R43*Assumptions!$B$4+S43*Assumptions!$B$5+T43*Assumptions!$B$6,0) -> 84 | V43: =IF(U43>=Assumptions!$B$10,"Healthy",IF(U43>=Assumptions!$B$11,"Needs Attention","High Risk")) -> Healthy
A44: ACC-10860 | B44: Orbitworks Ltd | C44: Enterprise | D44: Enterprise | E44: APAC | F44: James Carter | G44: 2027-06-01 | H44: 23220 | I44: 23220 | J44: 0.777 | K44: 10.7 | L44: 8 | M44: 1 | N44: Completed On Time | O44: =H44*12 -> 278640 | P44: =MIN(100,ROUND(100*J44/Assumptions!$B$8,0)) -> 86 | Q44: =IF(L44="",Assumptions!$B$9,L44*10) -> 80 | R44: =IF(M44<=1,Assumptions!$B$12,IF(M44<=3,Assumptions!$B$13,IF(M44<=6,Assumptions!$B$14,Assumptions!$B$15))) -> 100 | S44: =IF(N44="Completed On Time",Assumptions!$B$16,IF(N44="Completed Late",Assumptions!$B$17,Assumptions!$B$18)) -> 100 | T44: =IF(I44=0,Assumptions!$B$20,IF(H44>I44,Assumptions!$B$19,IF(H44=I44,Assumptions!$B$20,Assumptions!$B$21))) -> 70 | U44: =ROUND(P44*Assumptions!$B$2+Q44*Assumptions!$B$3+R44*Assumptions!$B$4+S44*Assumptions!$B$5+T44*Assumptions!$B$6,0) -> 85 | V44: =IF(U44>=Assumptions!$B$10,"Healthy",IF(U44>=Assumptions!$B$11,"Needs Attention","High Risk")) -> Healthy
A45: ACC-11798 | B45: Peakbridge Solutions | C45: Enterprise | D45: Enterprise | E45: EMEA | F45: Aisha Khan | G45: 2027-06-01 | H45: 23130 | I45: 23130 | J45: 0.846 | K45: 9.3 | L45: 10 | M45: 4 | N45: Completed On Time | O45: =H45*12 -> 277560 | P45: =MIN(100,ROUND(100*J45/Assumptions!$B$8,0)) -> 94 | Q45: =IF(L45="",Assumptions!$B$9,L45*10) -> 100 | R45: =IF(M45<=1,Assumptions!$B$12,IF(M45<=3,Assumptions!$B$13,IF(M45<=6,Assumptions!$B$14,Assumptions!$B$15))) -> 50 | S45: =IF(N45="Completed On Time",Assumptions!$B$16,IF(N45="Completed Late",Assumptions!$B$17,Assumptions!$B$18)) -> 100 | T45: =IF(I45=0,Assumptions!$B$20,IF(H45>I45,Assumptions!$B$19,IF(H45=I45,Assumptions!$B$20,Assumptions!$B$21))) -> 70 | U45: =ROUND(P45*Assumptions!$B$2+Q45*Assumptions!$B$3+R45*Assumptions!$B$4+S45*Assumptions!$B$5+T45*Assumptions!$B$6,0) -> 84 | V45: =IF(U45>=Assumptions!$B$10,"Healthy",IF(U45>=Assumptions!$B$11,"Needs Attention","High Risk")) -> Healthy
A46: ACC-10283 | B46: Greenpath Co | C46: Enterprise | D46: Enterprise | E46: APAC | F46: Rahul Mehta | G46: 2027-08-01 | H46: 23085 | I46: 23085 | J46: 0.561 | K46: 7.3 | L46: 4 | M46: 4 | N46: Completed Late | O46: =H46*12 -> 277020 | P46: =MIN(100,ROUND(100*J46/Assumptions!$B$8,0)) -> 62 | Q46: =IF(L46="",Assumptions!$B$9,L46*10) -> 40 | R46: =IF(M46<=1,Assumptions!$B$12,IF(M46<=3,Assumptions!$B$13,IF(M46<=6,Assumptions!$B$14,Assumptions!$B$15))) -> 50 | S46: =IF(N46="Completed On Time",Assumptions!$B$16,IF(N46="Completed Late",Assumptions!$B$17,Assumptions!$B$18)) -> 60 | T46: =IF(I46=0,Assumptions!$B$20,IF(H46>I46,Assumptions!$B$19,IF(H46=I46,Assumptions!$B$20,Assumptions!$B$21))) -> 70 | U46: =ROUND(P46*Assumptions!$B$2+Q46*Assumptions!$B$3+R46*Assumptions!$B$4+S46*Assumptions!$B$5+T46*Assumptions!$B$6,0) -> 57 | V46: =IF(U46>=Assumptions!$B$10,"Healthy",IF(U46>=Assumptions!$B$11,"Needs Attention","High Risk")) -> High Risk
A47: ACC-11584 | B47: Greenflow LLC | C47: Enterprise | D47: Enterprise | E47: North America | F47: Rahul Mehta | G47: 2027-01-01 | H47: 23085 | I47: 23085 | J47: 0.814 | K47: 8.3 | L47: 8 | M47: 5 | N47: Completed On Time | O47: =H47*12 -> 277020 | P47: =MIN(100,ROUND(100*J47/Assumptions!$B$8,0)) -> 90 | Q47: =IF(L47="",Assumptions!$B$9,L47*10) -> 80 | R47: =IF(M47<=1,Assumptions!$B$12,IF(M47<=3,Assumptions!$B$13,IF(M47<=6,Assumptions!$B$14,Assumptions!$B$15))) -> 50 | S47: =IF(N47="Completed On Time",Assumptions!$B$16,IF(N47="Completed Late",Assumptions!$B$17,Assumptions!$B$18)) -> 100 | T47: =IF(I47=0,Assumptions!$B$20,IF(H47>I47,Assumptions!$B$19,IF(H47=I47,Assumptions!$B$20,Assumptions!$B$21))) -> 70 | U47: =ROUND(P47*Assumptions!$B$2+Q47*Assumptions!$B$3+R47*Assumptions!$B$4+S47*Assumptions!$B$5+T47*Assumptions!$B$6,0) -> 79 | V47: =IF(U47>=Assumptions!$B$10,"Healthy",IF(U47>=Assumptions!$B$11,"Needs Attention","High Risk")) -> Needs Attention
A48: ACC-12025 | B48: Silversphere Inc | C48: Enterprise | D48: Enterprise | E48: APAC | F48: Aisha Khan | G48: 2027-08-01 | H48: 23040 | I48: 0 | J48: 0.749 | K48: 9 | M48: 3 | N48: In Progress | O48: =H48*12 -> 276480 | P48: =MIN(100,ROUND(100*J48/Assumptions!$B$8,0)) -> 83 | Q48: =IF(L48="",Assumptions!$B$9,L48*10) -> 50 | R48: =IF(M48<=1,Assumptions!$B$12,IF(M48<=3,Assumptions!$B$13,IF(M48<=6,Assumptions!$B$14,Assumptions!$B$15))) -> 75 | S48: =IF(N48="Completed On Time",Assumptions!$B$16,IF(N48="Completed Late",Assumptions!$B$17,Assumptions!$B$18)) -> 50 | T48: =IF(I48=0,Assumptions!$B$20,IF(H48>I48,Assumptions!$B$19,IF(H48=I48,Assumptions!$B$20,Assumptions!$B$21))) -> 70 | U48: =ROUND(P48*Assumptions!$B$2+Q48*Assumptions!$B$3+R48*Assumptions!$B$4+S48*Assumptions!$B$5+T48*Assumptions!$B$6,0) -> 69 | V48: =IF(U48>=Assumptions!$B$10,"Healthy",IF(U48>=Assumptions!$B$11,"Needs Attention","High Risk")) -> Needs Attention
A49: ACC-11680 | B49: Peakflow Solutions | C49: Enterprise | D49: Enterprise | E49: North America | F49: Rahul Mehta | G49: 2027-02-01 | H49: 22995 | I49: 22995 | J49: 0.761 | K49: 9 | L49: 9 | M49: 4 | N49: Completed On Time | O49: =H49*12 -> 275940 | P49: =MIN(100,ROUND(100*J49/Assumptions!$B$8,0)) -> 85 | Q49: =IF(L49="",Assumptions!$B$9,L49*10) -> 90 | R49: =IF(M49<=1,Assumptions!$B$12,IF(M49<=3,Assumptions!$B$13,IF(M49<=6,Assumptions!$B$14,Assumptions!$B$15))) -> 50 | S49: =IF(N49="Completed On Time",Assumptions!$B$16,IF(N49="Completed Late",Assumptions!$B$17,Assumptions!$B$18)) -> 100 | T49: =IF(I49=0,Assumptions!$B$20,IF(H49>I49,Assumptions!$B$19,IF(H49=I49,Assumptions!$B$20,Assumptions!$B$21))) -> 70 | U49: =ROUND(P49*Assumptions!$B$2+Q49*Assumptions!$B$3+R49*Assumptions!$B$4+S49*Assumptions!$B$5+T49*Assumptions!$B$6,0) -> 79 | V49: =IF(U49>=Assumptions!$B$10,"Healthy",IF(U49>=Assumptions!$B$11,"Needs Attention","High Risk")) -> Needs Attention
A50: ACC-10703 | B50: Atlaspath Technologies | C50: Enterprise | D50: Enterprise | E50: North America | F50: Daniel Brooks | G50: 2027-12-01 | H50: 22725 | I50: 22725 | J50: 0.745 | K50: 8.7 | L50: 6 | M50: 2 | N50: Completed On Time | O50: =H50*12 -> 272700 | P50: =MIN(100,ROUND(100*J50/Assumptions!$B$8,0)) -> 83 | Q50: =IF(L50="",Assumptions!$B$9,L50*10) -> 60 | R50: =IF(M50<=1,Assumptions!$B$12,IF(M50<=3,Assumptions!$B$13,IF(M50<=6,Assumptions!$B$14,Assumptions!$B$15))) -> 75 | S50: =IF(N50="Completed On Time",Assumptions!$B$16,IF(N50="Completed Late",Assumptions!$B$17,Assumptions!$B$18)) -> 100 | T50: =IF(I50=0,Assumptions!$B$20,IF(H50>I50,Assumptions!$B$19,IF(H50=I50,Assumptions!$B$20,Assumptions!$B$21))) -> 70 | U50: =ROUND(P50*Assumptions!$B$2+Q50*Assumptions!$B$3+R50*Assumptions!$B$4+S50*Assumptions!$B$5+T50*Assumptions!$B$6,0) -> 76 | V50: =IF(U50>=Assumptions!$B$10,"Healthy",IF(U50>=Assumptions!$B$11,"Needs Attention","High Risk")) -> Needs Attention
A51: ACC-11412 | B51: Vertexly Systems | C51: Enterprise | D51: Enterprise | E51: North America | F51: Daniel Brooks | G51: 2027-01-01 | H51: 22635 | I51: 22635 | J51: 0.618 | K51: 6 | L51: 9 | M51: 5 | N51: Completed Late | O51: =H51*12 -> 271620 | P51: =MIN(100,ROUND(100*J51/Assumptions!$B$8,0)) -> 69 | Q51: =IF(L51="",Assumptions!$B$9,L51*10) -> 90 | R51: =IF(M51<=1,Assumptions!$B$12,IF(M51<=3,Assumptions!$B$13,IF(M51<=6,Assumptions!$B$14,Assumptions!$B$15))) -> 50 | S51: =IF(N51="Completed On Time",Assumptions!$B$16,IF(N51="Completed Late",Assumptions!$B$17,Assumptions!$B$18)) -> 60 | T51: =IF(I51=0,Assumptions!$B$20,IF(H51>I51,Assumptions!$B$19,IF(H51=I51,Assumptions!$B$20,Assumptions!$B$21))) -> 70 | U51: =ROUND(P51*Assumptions!$B$2+Q51*Assumptions!$B$3+R51*Assumptions!$B$4+S51*Assumptions!$B$5+T51*Assumptions!$B$6,0) -> 70 | V51: =IF(U51>=Assumptions!$B$10,"Healthy",IF(U51>=Assumptions!$B$11,"Needs Attention","High Risk")) -> Needs Attention
A52: ACC-11780 | B52: Lumenscale Ltd | C52: Enterprise | D52: Enterprise | E52: EMEA | F52: Lucas Martin | G52: 2027-06-01 | H52: 22455 | I52: 22455 | J52: 0.643 | K52: 7.3 | L52: 8 | M52: 9 | N52: Completed On Time | O52: =H52*12 -> 269460 | P52: =MIN(100,ROUND(100*J52/Assumptions!$B$8,0)) -> 71 | Q52: =IF(L52="",Assumptions!$B$9,L52*10) -> 80 | R52: =IF(M52<=1,Assumptions!$B$12,IF(M52<=3,Assumptions!$B$13,IF(M52<=6,Assumptions!$B$14,Assumptions!$B$15))) -> 20 | S52: =IF(N52="Completed On Time",Assumptions!$B$16,IF(N52="Completed Late",Assumptions!$B$17,Assumptions!$B$18)) -> 100 | T52: =IF(I52=0,Assumptions!$B$20,IF(H52>I52,Assumptions!$B$19,IF(H52=I52,Assumptions!$B$20,Assumptions!$B$21))) -> 70 | U52: =ROUND(P52*Assumptions!$B$2+Q52*Assumptions!$B$3+R52*Assumptions!$B$4+S52*Assumptions!$B$5+T52*Assumptions!$B$6,0) -> 68 | V52: =IF(U52>=Assumptions!$B$10,"Healthy",IF(U52>=Assumptions!$B$11,"Needs Attention","High Risk")) -> Needs Attention
A53: ACC-10653 | B53: Lumenmind Group | C53: Enterprise | D53: Enterprise | E53: EMEA | F53: Sofia Alvarez | G53: 2027-01-01 | H53: 22230 | I53: 22230 | J53: 0.627 | K53: 11 | L53: 8 | M53: 1 | N53: Completed On Time | O53: =H53*12 -> 266760 | P53: =MIN(100,ROUND(100*J53/Assumptions!$B$8,0)) -> 70 | Q53: =IF(L53="",Assumptions!$B$9,L53*10) -> 80 | R53: =IF(M53<=1,Assumptions!$B$12,IF(M53<=3,Assumptions!$B$13,IF(M53<=6,Assumptions!$B$14,Assumptions!$B$15))) -> 100 | S53: =IF(N53="Completed On Time",Assumptions!$B$16,IF(N53="Completed Late",Assumptions!$B$17,Assumptions!$B$18)) -> 100 | T53: =IF(I53=0,Assumptions!$B$20,IF(H53>I53,Assumptions!$B$19,IF(H53=I53,Assumptions!$B$20,Assumptions!$B$21))) -> 70 | U53: =ROUND(P53*Assumptions!$B$2+Q53*Assumptions!$B$3+R53*Assumptions!$B$4+S53*Assumptions!$B$5+T53*Assumptions!$B$6,0) -> 80 | V53: =IF(U53>=Assumptions!$B$10,"Healthy",IF(U53>=Assumptions!$B$11,"Needs Attention","High Risk")) -> Healthy
A54: ACC-10863 | B54: Brightforge Co | C54: Enterprise | D54: Enterprise | E54: APAC | F54: Sofia Alvarez | G54: 2027-04-01 | H54: 22140 | I54: 22140 | J54: 0.751 | K54: 9.3 | L54: 9 | M54: 6 | N54: Completed On Time | O54: =H54*12 -> 265680 | P54: =MIN(100,ROUND(100*J54/Assumptions!$B$8,0)) -> 83 | Q54: =IF(L54="",Assumptions!$B$9,L54*10) -> 90 | R54: =IF(M54<=1,Assumptions!$B$12,IF(M54<=3,Assumptions!$B$13,IF(M54<=6,Assumptions!$B$14,Assumptions!$B$15))) -> 50 | S54: =IF(N54="Completed On Time",Assumptions!$B$16,IF(N54="Completed Late",Assumptions!$B$17,Assumptions!$B$18)) -> 100 | T54: =IF(I54=0,Assumptions!$B$20,IF(H54>I54,Assumptions!$B$19,IF(H54=I54,Assumptions!$B$20,Assumptions!$B$21))) -> 70 | U54: =ROUND(P54*Assumptions!$B$2+Q54*Assumptions!$B$3+R54*Assumptions!$B$4+S54*Assumptions!$B$5+T54*Assumptions!$B$6,0) -> 79 | V54: =IF(U54>=Assumptions!$B$10,"Healthy",IF(U54>=Assumptions!$B$11,"Needs Attention","High Risk")) -> Needs Attention
A55: ACC-10080 | B55: Orbitnest LLC | C55: Enterprise | D55: Enterprise | E55: North America | F55: Sofia Alvarez | G55: 2027-04-01 | H55: 21915 | I55: 21915 | J55: 0.863 | K55: 11 | L55: 9 | M55: 5 | N55: Completed On Time | O55: =H55*12 -> 262980 | P55: =MIN(100,ROUND(100*J55/Assumptions!$B$8,0)) -> 96 | Q55: =IF(L55="",Assumptions!$B$9,L55*10) -> 90 | R55: =IF(M55<=1,Assumptions!$B$12,IF(M55<=3,Assumptions!$B$13,IF(M55<=6,Assumptions!$B$14,Assumptions!$B$15))) -> 50 | S55: =IF(N55="Completed On Time",Assumptions!$B$16,IF(N55="Completed Late",Assumptions!$B$17,Assumptions!$B$18)) -> 100 | T55: =IF(I55=0,Assumptions!$B$20,IF(H55>I55,Assumptions!$B$19,IF(H55=I55,Assumptions!$B$20,Assumptions!$B$21))) -> 70 | U55: =ROUND(P55*Assumptions!$B$2+Q55*Assumptions!$B$3+R55*Assumptions!$B$4+S55*Assumptions!$B$5+T55*Assumptions!$B$6,0) -> 83 | V55: =IF(U55>=Assumptions!$B$10,"Healthy",IF(U55>=Assumptions!$B$11,"Needs Attention","High Risk")) -> Healthy
...

Sheet Monthly_MRR
A1: Month | B1: Total MRR | C1: Paying customers | D1: New MRR | E1: Expansion MRR | F1: Contraction MRR | G1: Churned MRR | H1: Customers at start | I1: Customers churned | J1: ARR | K1: Net new MRR | L1: MoM MRR growth | M1: Logo churn rate | N1: Avg MRR per customer
A2: 45292 | B2: 1149201 | C2: 476 | D2: 0 | E2: 0 | F2: 0 | G2: 0 | H2: 0 | I2: 0 | J2: =B2*12 -> 13790412 | K2: =D2+E2-F2-G2 -> 0 | M2: =IFERROR(I2/H2,0) -> 0 | N2: =IFERROR(B2/C2,0) -> 2414.2878
A3: 45323 | B3: 1283681 | C3: 536 | D3: 134480 | E3: 0 | F3: 0 | G3: 0 | H3: 476 | I3: 0 | J3: =B3*12 -> 15404172 | K3: =D3+E3-F3-G3 -> 134480 | L3: =IFERROR(B3/B2-1,0) -> 0.11702043 | M3: =IFERROR(I3/H3,0) -> 0 | N3: =IFERROR(B3/C3,0) -> 2394.9272
A4: 45352 | B4: 1473385 | C4: 603 | D4: 183727 | E4: 10627 | F4: 550 | G4: 4100 | H4: 536 | I4: 3 | J4: =B4*12 -> 17680620 | K4: =D4+E4-F4-G4 -> 189704 | L4: =IFERROR(B4/B3-1,0) -> 0.14778126 | M4: =IFERROR(I4/H4,0) -> 0.0055970149 | N4: =IFERROR(B4/C4,0) -> 2443.4245
A5: 45383 | B5: 1663172 | C5: 672 | D5: 198114 | E5: 10714 | F5: 1684 | G5: 17357 | H5: 603 | I5: 6 | J5: =B5*12 -> 19958064 | K5: =D5+E5-F5-G5 -> 189787 | L5: =IFERROR(B5/B4-1,0) -> 0.12881019 | M5: =IFERROR(I5/H5,0) -> 0.0099502488 | N5: =IFERROR(B5/C5,0) -> 2474.9583
A6: 45413 | B6: 1884399 | C6: 734 | D6: 241615 | E6: 8260 | F6: 6289 | G6: 22359 | H6: 672 | I6: 8 | J6: =B6*12 -> 22612788 | K6: =D6+E6-F6-G6 -> 221227 | L6: =IFERROR(B6/B5-1,0) -> 0.13301511 | M6: =IFERROR(I6/H6,0) -> 0.011904762 | N6: =IFERROR(B6/C6,0) -> 2567.3011
A7: 45444 | B7: 2081709 | C7: 791 | D7: 200309 | E7: 7128 | F7: 625 | G7: 9502 | H7: 734 | I7: 9 | J7: =B7*12 -> 24980508 | K7: =D7+E7-F7-G7 -> 197310 | L7: =IFERROR(B7/B6-1,0) -> 0.10470712 | M7: =IFERROR(I7/H7,0) -> 0.01226158 | N7: =IFERROR(B7/C7,0) -> 2631.7434
A8: 45474 | B8: 2272819 | C8: 857 | D8: 212045 | E8: 10429 | F8: 224 | G8: 31140 | H8: 791 | I8: 9 | J8: =B8*12 -> 27273828 | K8: =D8+E8-F8-G8 -> 191110 | L8: =IFERROR(B8/B7-1,0) -> 0.091804378 | M8: =IFERROR(I8/H8,0) -> 0.011378003 | N8: =IFERROR(B8/C8,0) -> 2652.0642
A9: 45505 | B9: 2449938 | C9: 909 | D9: 207264 | E9: 6220 | F9: 375 | G9: 35990 | H9: 857 | I9: 11 | J9: =B9*12 -> 29399256 | K9: =D9+E9-F9-G9 -> 177119 | L9: =IFERROR(B9/B8-1,0) -> 0.077929215 | M9: =IFERROR(I9/H9,0) -> 0.012835473 | N9: =IFERROR(B9/C9,0) -> 2695.2013
A10: 45536 | B10: 2591221 | C10: 979 | D10: 162778 | E10: 7024 | F10: 802 | G10: 27717 | H10: 909 | I10: 9 | J10: =B10*12 -> 31094652 | K10: =D10+E10-F10-G10 -> 141283 | L10: =IFERROR(B10/B9-1,0) -> 0.05766799 | M10: =IFERROR(I10/H10,0) -> 0.0099009901 | N10: =IFERROR(B10/C10,0) -> 2646.8039
A11: 45566 | B11: 2793700 | C11: 1025 | D11: 224718 | E11: 3006 | F11: 2356 | G11: 22889 | H11: 979 | I11: 17 | J11: =B11*12 -> 33524400 | K11: =D11+E11-F11-G11 -> 202479 | L11: =IFERROR(B11/B10-1,0) -> 0.078140382 | M11: =IFERROR(I11/H11,0) -> 0.017364658 | N11: =IFERROR(B11/C11,0) -> 2725.561
A12: 45597 | B12: 2979314 | C12: 1095 | D12: 223020 | E12: 16716 | F12: 3814 | G12: 50308 | H12: 1025 | I12: 10 | J12: =B12*12 -> 35751768 | K12: =D12+E12-F12-G12 -> 185614 | L12: =IFERROR(B12/B11-1,0) -> 0.066440205 | M12: =IFERROR(I12/H12,0) -> 0.0097560976 | N12: =IFERROR(B12/C12,0) -> 2720.8347
A13: 45627 | B13: 3140350 | C13: 1140 | D13: 171822 | E13: 8329 | F13: 2400 | G13: 16715 | H13: 1095 | I13: 10 | J13: =B13*12 -> 37684200 | K13: =D13+E13-F13-G13 -> 161036 | L13: =IFERROR(B13/B12-1,0) -> 0.054051369 | M13: =IFERROR(I13/H13,0) -> 0.0091324201 | N13: =IFERROR(B13/C13,0) -> 2754.693
A14: 45658 | B14: 3319851 | C14: 1207 | D14: 181053 | E14: 16704 | F14: 1631 | G14: 16625 | H14: 1140 | I14: 9 | J14: =B14*12 -> 39838212 | K14: =D14+E14-F14-G14 -> 179501 | L14: =IFERROR(B14/B13-1,0) -> 0.057159552 | M14: =IFERROR(I14/H14,0) -> 0.0078947368 | N14: =IFERROR(B14/C14,0) -> 2750.4979
... A34: 46266 | B34: 6299607 | C34: 2121 | D34: 0 | E34: 42446 | F34: 1714 | G34: 48717 | H34: 2139 | I34: 18 | J34: =B34*12 -> 75595284 | K34: =D34+E34-F34-G34 -> -7985 | L34: =IFERROR(B34/B33-1,0) -> -0.0012659348 | M34: =IFERROR(I34/H34,0) -> 0.0084151473 | N34: =IFERROR(B34/C34,0) -> 2970.1117
A36: Jan 2024 movement columns are 0 because there is no prior month to compare against.

Sheet Retention_Cohort
A1: account_id | B1: segment | C1: MRR Sep 2025 | D1: MRR Sep 2026 | E1: Retained MRR (capped) | F1: Still a customer?
A2: ACC-11133 | B2: Enterprise | C2: 32985 | D2: 32985 | E2: =MIN(C2,D2) -> 32985 | F2: =IF(D2>0,1,0) -> 1
A3: ACC-12113 | B3: Enterprise | C3: 31725 | D3: 0 | E3: =MIN(C3,D3) -> 0 | F3: =IF(D3>0,1,0) -> 0
A4: ACC-11722 | B4: Enterprise | C4: 31275 | D4: 31275 | E4: =MIN(C4,D4) -> 31275 | F4: =IF(D4>0,1,0) -> 1
A5: ACC-11225 | B5: Enterprise | C5: 29925 | D5: 29925 | E5: =MIN(C5,D5) -> 29925 | F5: =IF(D5>0,1,0) -> 1
A6: ACC-12391 | B6: Enterprise | C6: 29745 | D6: 29745 | E6: =MIN(C6,D6) -> 29745 | F6: =IF(D6>0,1,0) -> 1
A7: ACC-12541 | B7: Enterprise | C7: 29655 | D7: 34785 | E7: =MIN(C7,D7) -> 29655 | F7: =IF(D7>0,1,0) -> 1
A8: ACC-12420 | B8: Enterprise | C8: 28035 | D8: 28035 | E8: =MIN(C8,D8) -> 28035 | F8: =IF(D8>0,1,0) -> 1
A9: ACC-11707 | B9: Enterprise | C9: 26775 | D9: 26775 | E9: =MIN(C9,D9) -> 26775 | F9: =IF(D9>0,1,0) -> 1
A10: ACC-11275 | B10: Enterprise | C10: 26730 | D10: 26730 | E10: =MIN(C10,D10) -> 26730 | F10: =IF(D10>0,1,0) -> 1
A11: ACC-11371 | B11: Enterprise | C11: 26640 | D11: 26640 | E11: =MIN(C11,D11) -> 26640 | F11: =IF(D11>0,1,0) -> 1
A12: ACC-10275 | B12: Enterprise | C12: 26550 | D12: 26550 | E12: =MIN(C12,D12) -> 26550 | F12: =IF(D12>0,1,0) -> 1
A13: ACC-10743 | B13: Enterprise | C13: 26325 | D13: 26325 | E13: =MIN(C13,D13) -> 26325 | F13: =IF(D13>0,1,0) -> 1
... A1621: ACC-11507 | B1621: SMB | C1621: 48 | D1621: 0 | E1621: =MIN(C1621,D1621) -> 0 | F1621: =IF(D1621>0,1,0) -> 0

Sheet NPS_Responses
A1: response_id | B1: account_id | C1: segment | D1: survey_date | E1: nps_score | F1: Category
A2: NPS-02444 | B2: ACC-10860 | C2: Enterprise | D2: 45901 | E2: 10 | F2: =IF(E2>=9,"Promoter",IF(E2>=7,"Passive","Detractor")) -> Promoter
A3: NPS-04278 | B3: ACC-11535 | C3: Mid-Market | D3: 45901 | E3: 6 | F3: =IF(E3>=9,"Promoter",IF(E3>=7,"Passive","Detractor")) -> Detractor
A4: NPS-05102 | B4: ACC-11817 | C4: Enterprise | D4: 45901 | E4: 10 | F4: =IF(E4>=9,"Promoter",IF(E4>=7,"Passive","Detractor")) -> Promoter
A5: NPS-06575 | B5: ACC-12343 | C5: SMB | D5: 45901 | E5: 8 | F5: =IF(E5>=9,"Promoter",IF(E5>=7,"Passive","Detractor")) -> Passive
A6: NPS-06944 | B6: ACC-12475 | C6: SMB | D6: 45901 | E6: 7 | F6: =IF(E6>=9,"Promoter",IF(E6>=7,"Passive","Detractor")) -> Passive
A7: NPS-01880 | B7: ACC-10656 | C7: SMB | D7: 45902 | E7: 7 | F7: =IF(E7>=9,"Promoter",IF(E7>=7,"Passive","Detractor")) -> Passive
A8: NPS-06879 | B8: ACC-12448 | C8: SMB | D8: 45902 | E8: 7 | F8: =IF(E8>=9,"Promoter",IF(E8>=7,"Passive","Detractor")) -> Passive
A9: NPS-00066 | B9: ACC-10021 | C9: SMB | D9: 45903 | E9: 6 | F9: =IF(E9>=9,"Promoter",IF(E9>=7,"Passive","Detractor")) -> Detractor
A10: NPS-00442 | B10: ACC-10165 | C10: SMB | D10: 45903 | E10: 10 | F10: =IF(E10>=9,"Promoter",IF(E10>=7,"Passive","Detractor")) -> Promoter
A11: NPS-00519 | B11: ACC-10192 | C11: SMB | D11: 45903 | E11: 9 | F11: =IF(E11>=9,"Promoter",IF(E11>=7,"Passive","Detractor")) -> Promoter
A12: NPS-01833 | B12: ACC-10643 | C12: Mid-Market | D12: 45903 | E12: 9 | F12: =IF(E12>=9,"Promoter",IF(E12>=7,"Passive","Detractor")) -> Promoter
A13: NPS-02010 | B13: ACC-10703 | C13: Enterprise | D13: 45903 | E13: 8 | F13: =IF(E13>=9,"Promoter",IF(E13>=7,"Passive","Detractor")) -> Passive
... A4016: NPS-05547 | B4016: ACC-11975 | C4016: SMB | D4016: 46290 | E4016: 10 | F4016: =IF(E4016>=9,"Promoter",IF(E4016>=7,"Passive","Detractor")) -> Promoter

Sheet Accounts
A1: account_id | B1: company_name | C1: industry | D1: region | E1: segment | F1: plan | G1: csm_owner | H1: acquisition_channel | I1: signup_date | J1: renewal_date | K1: status | L1: churn_date | M1: churn_reason | N1: price_per_seat | O1: contracted_seats_at_start | P1: onboarding_status
A2: ACC-10001 | B2: Blueline Technologies | C2: Logistics | D2: EMEA | E2: Mid-Market | F2: Growth | G2: Neha Iyer | H2: Inbound | I2: 2025-02-25 | J2: 2027-02-01 | K2: Active | N2: 25 | O2: 110 | P2: Completed Late
A3: ACC-10002 | B3: Lumenforge Solutions | C3: Manufacturing | D3: North America | E3: Mid-Market | F3: Growth | G3: Sofia Alvarez | H3: Outbound | I3: 2025-10-23 | J3: 2027-10-01 | K3: Active | N3: 25 | O3: 68 | P3: Completed Late
A4: ACC-10003 | B4: Vertexnest Group | C4: Manufacturing | D4: LATAM | E4: SMB | F4: Starter | G4: Lucas Martin | H4: Outbound | I4: 2026-06-26 | J4: 2027-06-01 | K4: Active | N4: 12 | O4: 27 | P4: Completed On Time
A5: ACC-10004 | B5: Vertexly LLC | C5: Healthcare | D5: North America | E5: Mid-Market | F5: Growth | G5: Rahul Mehta | H5: Self-serve | I5: 2024-09-19 | J5: 2027-09-01 | K5: Active | N5: 25 | O5: 160 | P5: Completed On Time
A6: ACC-10005 | B6: Northsphere Technologies | C6: Manufacturing | D6: APAC | E6: SMB | F6: Growth | G6: Rahul Mehta | H6: Inbound | I6: 2026-08-04 | J6: 2027-08-01 | K6: Active | N6: 25 | O6: 30 | P6: Completed On Time
A7: ACC-10006 | B7: Novaflow Group | C7: Healthcare | D7: APAC | E7: SMB | F7: Growth | G7: Rahul Mehta | H7: Outbound | I7: 2026-01-11 | J7: 2027-01-01 | K7: Active | N7: 25 | O7: 31 | P7: Completed On Time
A8: ACC-10007 | B8: Swiftnest Co | C8: Media & Marketing | D8: APAC | E8: Enterprise | F8: Enterprise | G8: Rahul Mehta | H8: Partner | I8: 2024-09-30 | J8: 2027-09-01 | K8: Active | N8: 45 | O8: 151 | P8: Completed On Time
A9: ACC-10008 | B9: Swiftsphere Co | C9: Healthcare | D9: APAC | E9: Enterprise | F9: Enterprise | G9: Neha Iyer | H9: Partner | I9: 2025-08-08 | J9: 2027-08-01 | K9: Active | N9: 45 | O9: 197 | P9: Completed On Time
A10: ACC-10009 | B10: Northcraft Solutions | C10: Technology | D10: North America | E10: SMB | F10: Starter | G10: Aisha Khan | H10: Inbound | I10: 2024-10-11 | J10: 2027-10-01 | K10: Active | N10: 12 | O10: 38 | P10: Completed On Time
A11: ACC-10010 | B11: Brightstack Solutions | C11: Financial Services | D11: North America | E11: SMB | F11: Growth | G11: Aisha Khan | H11: Inbound | I11: 2025-10-27 | J11: 2027-10-01 | K11: Active | N11: 25 | O11: 19 | P11: Completed On Time
A12: ACC-10011 | B12: Peakwave Inc | C12: Manufacturing | D12: North America | E12: Enterprise | F12: Growth | G12: Daniel Brooks | H12: Partner | I12: 2023-11-30 | J12: 2027-11-01 | K12: Active | N12: 25 | O12: 163 | P12: Completed On Time
A13: ACC-10012 | B13: Primescale Group | C13: Media & Marketing | D13: EMEA | E13: SMB | F13: Starter | G13: Neha Iyer | H13: Outbound | I13: 2024-04-21 | J13: 2027-04-01 | K13: Active | N13: 12 | O13: 20 | P13: Completed On Time
... A15: ACC-10014 | B15: Brightwave Solutions | C15: Financial Services | D15: APAC | E15: SMB | F15: Starter | G15: Neha Iyer | H15: Outbound | I15: 2023-08-09 | J15: 2027-08-01 | K15: Active | N15: 12 | O15: 36 | P15: Completed On Time
A16: ACC-10015 | B16: Northsphere LLC | C16: Education | D16: LATAM | E16: Mid-Market | F16: Enterprise | G16: Daniel Brooks | H16: Outbound | I16: 2023-10-14 | K16: Churned | L16: 2024-10-17 | M16: Low adoption | N16: 45 | O16: 79 | P16: Completed On Time
A17: ACC-10016 | B17: Corebase Solutions | C17: Manufacturing | D17: APAC | E17: SMB | F17: Growth | G17: Neha Iyer | H17: Outbound | I17: 2025-04-17 | K17: Churned | L17: 2025-11-19 | M17: Switched to competitor | N17: 25 | O17: 8 | P17: Completed On Time
A18: ACC-10017 | B18: Northstack Ltd | C18: Financial Services | D18: North America | E18: Mid-Market | F18: Growth | G18: Aisha Khan | H18: Inbound | I18: 2024-02-10 | J18: 2027-02-01 | K18: Active | N18: 25 | O18: 114 | P18: Completed On Time
A19: ACC-10018 | B19: Greenhub Group | C19: Media & Marketing | D19: EMEA | E19: Mid-Market | F19: Enterprise | G19: Priya Sharma | H19: Self-serve | I19: 2025-04-21 | J19: 2027-04-01 | K19: Active | N19: 45 | O19: 92 | P19: Completed On Time
A20: ACC-10019 | B20: Apexstack Co | C20: Technology | D20: North America | E20: SMB | F20: Starter | G20: Neha Iyer | H20: Partner | I20: 2024-04-26 | J20: 2027-04-01 | K20: Active | N20: 12 | O20: 21 | P20: Completed On Time
A21: ACC-10020 | B21: Vertexhub Ltd | C21: Retail & E-commerce | D21: LATAM | E21: Enterprise | F21: Enterprise | G21: Sofia Alvarez | H21: Partner | I21: 2024-04-24 | J21: 2027-04-01 | K21: Active | N21: 45 | O21: 385 | P21: Completed On Time
A22: ACC-10021 | B22: Atlashub LLC | C22: Financial Services | D22: EMEA | E22: SMB | F22: Starter | G22: Priya Sharma | H22: Partner | I22: 2024-06-19 | K22: Churned | L22: 2026-03-23 | M22: Budget cuts | N22: 12 | O22: 23 | P22: Completed On Time
A23: ACC-10022 | B23: Primelogic Group | C23: Manufacturing | D23: North America | E23: SMB | F23: Starter | G23: Sofia Alvarez | H23: Self-serve | I23: 2025-12-06 | J23: 2027-12-01 | K23: Active | N23: 12 | O23: 20 | P23: Completed On Time
A24: ACC-10023 | B24: Greenforge Ltd | C24: Technology | D24: APAC | E24: SMB | F24: Starter | G24: Aisha Khan | H24: Partner | I24: 2024-07-26 | J24: 2027-07-01 | K24: Active | N24: 12 | O24: 17 | P24: Completed On Time
A25: ACC-10024 | B25: Pixelpath Technologies | C25: Media & Marketing | D25: North America | E25: SMB | F25: Starter | G25: Marco Rossi | H25: Inbound | I25: 2025-07-07 | J25: 2027-07-01 | K25: Active | N25: 12 | O25: 11 | P25: Completed On Time
A26: ACC-10025 | B26: Northscale Co | C26: Healthcare | D26: LATAM | E26: Mid-Market | F26: Growth | G26: Rahul Mehta | H26: Partner | I26: 2024-10-20 | J26: 2027-10-01 | K26: Active | N26: 25 | O26: 159 | P26: Completed On Time
A27: ACC-10026 | B27: Corecraft Technologies | C27: Retail & E-commerce | D27: North America | E27: Mid-Market | F27: Growth | G27: Sofia Alvarez | H27: Inbound | I27: 2026-06-30 | J27: 2027-06-01 | K27: Active | N27: 25 | O27: 160 | P27: Completed Late
A28: ACC-10027 | B28: Silverlabs Co | C28: Healthcare | D28: EMEA | E28: Mid-Market | F28: Growth | G28: Neha Iyer | H28: Self-serve | I28: 2024-11-21 | K28: Churned | L28: 2026-07-16 | M28: Switched to competitor | N28: 25 | O28: 141 | P28: Completed On Time
A29: ACC-10028 | B29: Blueflow Co | C29: Education | D29: EMEA | E29: SMB | F29: Starter | G29: Sofia Alvarez | H29: Self-serve | I29: 2026-01-03 | J29: 2027-01-01 | K29: Active | N29: 12 | O29: 32 | P29: Completed On Time
A30: ACC-10029 | B30: Swiftwave Group | C30: Healthcare | D30: North America | E30: SMB | F30: Growth | G30: Lucas Martin | H30: Inbound | I30: 2025-08-21 | J30: 2027-08-01 | K30: Active | N30: 25 | O30: 6 | P30: Completed On Time
A31: ACC-10030 | B31: Vertexgrid Group | C31: Healthcare | D31: APAC | E31: SMB | F31: Growth | G31: Priya Sharma | H31: Outbound | I31: 2023-07-01 | J31: 2027-07-01 | K31: Active | N31: 25 | O31: 21 | P31: Completed On Time
A32: ACC-10031 | B32: Pixelcraft Co | C32: Media & Marketing | D32: EMEA | E32: Enterprise | F32: Enterprise | G32: Lucas Martin | H32: Self-serve | I32: 2023-07-16 | J32: 2027-07-01 | K32: Active | N32: 45 | O32: 480 | P32: Completed On Time
A33: ACC-10032 | B33: Vertexstack Co | C33: Healthcare | D33: EMEA | E33: Mid-Market | F33: Growth | G33: James Carter | H33: Outbound | I33: 2026-03-20 | K33: Churned | L33: 2026-09-24 | M33: Poor onboarding experience | N33: 25 | O33: 182 | P33: Completed On Time
A34: ACC-10033 | B34: Trueworks LLC | C34: Healthcare | D34: North America | E34: Mid-Market | F34: Growth | G34: Neha Iyer | H34: Self-serve | I34: 2026-04-04 | J34: 2027-04-01 | K34: Active | N34: 25 | O34: 192 | P34: Completed On Time
